{
  "uuid": "3e633cb4-ce18-46aa-9f56-b625de7b1fef",
  "path": "/usr/lib/python3.12/lib2to3/fixes/__pycache__/fix_next.cpython-312.pyc",
  "size": 4362,
  "modified": "2025-05-28T17:29:55.211456973Z",
  "created": "2025-05-28T17:29:55.211456973Z",
  "sha256_hash": "c24d06315187c983a9d0ef3111c944785a43c9280175a05c83958c805d8c33a3",
  "file_type": {
    "Other": "pyc"
  },
  "permissions": 33188,
  "is_executable": true,
  "is_signed": false,
  "code_signature": null,
  "bundle_info": null,
  "scan_timestamp": "2025-06-01T18:46:04.910777384Z"
}