{
  "uuid": "6cdf8e0a-bb08-4ae9-8f67-8873c78ae8aa",
  "path": "/usr/lib/python3.12/test/test_capi/__pycache__/test_exceptions.cpython-312.pyc",
  "size": 27658,
  "modified": "2025-05-28T17:29:53.651477457Z",
  "created": "2025-05-28T17:29:53.651477457Z",
  "sha256_hash": "de52611e8d769df68eb23b2faa745cc71c83cc847f62a9cd1961796ab9cd71c9",
  "file_type": {
    "Other": "pyc"
  },
  "permissions": 33188,
  "is_executable": true,
  "is_signed": false,
  "code_signature": null,
  "bundle_info": null,
  "scan_timestamp": "2025-06-01T18:46:03.701305422Z"
}