{
  "uuid": "a270a025-7f61-43e8-b576-55e1d7486c4e",
  "path": "/lib/python3.12/lib2to3/fixes/__pycache__/fix_except.cpython-312.pyc",
  "size": 4028,
  "modified": "2025-05-28T17:29:55.207457025Z",
  "created": "2025-05-28T17:29:55.207457025Z",
  "sha256_hash": "984e948df8487555033efb8ad56b0548688ce7bc85fef4fee6839a7855efc7d6",
  "file_type": {
    "Other": "pyc"
  },
  "permissions": 33188,
  "is_executable": false,
  "is_signed": false,
  "code_signature": null,
  "bundle_info": null,
  "scan_timestamp": "2025-06-01T18:47:09.185001765Z"
}