{
  "uuid": "a9d9ef9a-95fc-40e0-a68d-c69b7cb47dd2",
  "path": "/lib/python3/dist-packages/aptdaemon/__pycache__/errors.cpython-312.pyc",
  "size": 9862,
  "modified": "2025-02-15T08:14:20Z",
  "created": "2025-05-09T05:07:26.517796408Z",
  "sha256_hash": "3b9d513dd8214bee694b5e56b9bb73243fdb89b0d7dedca485e66af0eb2db03e",
  "file_type": {
    "Other": "pyc"
  },
  "permissions": 33188,
  "is_executable": false,
  "is_signed": false,
  "code_signature": null,
  "bundle_info": null,
  "scan_timestamp": "2025-06-01T18:46:34.410953980Z"
}